<?xml version="1.0" encoding="utf-8"?>
<robot name="assy3_v3">
	<link name="base_v2:1">
		<inertial>
			<mass value="11.77943907041952"/>
			<origin rpy="0 0 0" xyz="0.075 6.061013063725804e-18 -1.2122026127451608e-17"/>
			<inertia ixx="0.01962779439482778" ixy="-3.5697667044587477e-19" ixz="-2.1632786229019983e-16" iyy="0.03191730640267711" iyz="5.711626727133988e-18" izz="0.0319200808216919"/>
		</inertial>
		<collision name="base_v2:1_collision">
			<origin rpy="0.0 -0.0 0.0" xyz="0.0 0.0 0.0"/>
			<geometry>
				<mesh filename="./meshes/base_v2.stl" scale="1.0 1.0 1.0"/>
			</geometry>
		</collision>
		<visual name="base_v2:1_visual">
			<origin rpy="0.0 -0.0 0.0" xyz="0.0 0.0 0.0"/>
			<geometry>
				<mesh filename="./meshes/base_v2.stl" scale="1.0 1.0 1.0"/>
			</geometry>
		</visual>
	</link>
	<link name="1_v3:1">
		<inertial>
			<mass value="0.1671112159555787"/>
			<origin rpy="0 0 0" xyz="0.0024999999999999745 -0.060807907091331714 -0.0793876466156504"/>
			<inertia ixx="0.0006407520425395866" ixy="3.552713678800501e-19" ixz="0.0" iyy="0.0004027334414290557" iyz="-0.00030397094497378323" izz="0.00023871489784368195"/>
		</inertial>
		<collision name="1_v3:1_collision">
			<origin rpy="0.13175950392909871 -0.0 6.123233995736766e-17" xyz="0.0 6.938893903907228e-18 1.1337381322698146e-18"/>
			<geometry>
				<mesh filename="./meshes/1_v3.stl" scale="1.0 1.0 1.0"/>
			</geometry>
		</collision>
		<visual name="1_v3:1_visual">
			<origin rpy="0.13175950392909871 -0.0 6.123233995736766e-17" xyz="0.0 6.938893903907228e-18 1.1337381322698146e-18"/>
			<geometry>
				<mesh filename="./meshes/1_v3.stl" scale="1.0 1.0 1.0"/>
			</geometry>
		</visual>
	</link>
	<link name="2_v1:1">
		<inertial>
			<mass value="0.1514112159555787"/>
			<origin rpy="0 0 0" xyz="0.0025000000000000022 0.06377944604287848 0.06349946663133588"/>
			<inertia ixx="0.00047814739889065407" ixy="-3.552713678800501e-19" ixz="0.0" iyy="0.00023835940436346662" iyz="-0.00023405815947949958" izz="0.00024041887459366932"/>
		</inertial>
		<collision name="2_v1:1_collision">
			<origin rpy="-0.0021997277795369353 -0.0 6.123233995736766e-17" xyz="0.0 0.12755889208575696 0.12699893326266257"/>
			<geometry>
				<mesh filename="./meshes/2_v1.stl" scale="1.0 1.0 1.0"/>
			</geometry>
		</collision>
		<visual name="2_v1:1_visual">
			<origin rpy="-0.0021997277795369353 -0.0 6.123233995736766e-17" xyz="0.0 0.12755889208575696 0.12699893326266257"/>
			<geometry>
				<mesh filename="./meshes/2_v1.stl" scale="1.0 1.0 1.0"/>
			</geometry>
		</visual>
	</link>
	<link name="3_v1:1">
		<inertial>
			<mass value="0.12786121595557864"/>
			<origin rpy="0 0 0" xyz="0.00250000000000003 -0.050597767108932185 0.05536123159387263"/>
			<inertia ixx="0.00029003838940059765" ixy="0.0" ixz="0.0" iyy="0.00015791875842323435" iyz="0.0001402229857267848" izz="0.00013265238604384563"/>
		</inertial>
		<collision name="3_v1:1_collision">
			<origin rpy="-0.6557907227074701 -0.0 5.004030080335416e-17" xyz="0.0 0.0 0.0"/>
			<geometry>
				<mesh filename="./meshes/3_v1.stl" scale="1.0 1.0 1.0"/>
			</geometry>
		</collision>
		<visual name="3_v1:1_visual">
			<origin rpy="-0.6557907227074701 -0.0 5.004030080335416e-17" xyz="0.0 0.0 0.0"/>
			<geometry>
				<mesh filename="./meshes/3_v1.stl" scale="1.0 1.0 1.0"/>
			</geometry>
		</visual>
	</link>
	<link name="4_v3:1">
		<inertial>
			<mass value="0.12389251594210231"/>
			<origin rpy="0 0 0" xyz="-0.007047148450609303 0.016036461575005295 -0.017327390104917302"/>
			<inertia ixx="0.00022687706672765487" ixy="8.997243585668002e-07" ixz="-9.72151797535936e-07" iyy="0.0001952384569315896" iyz="6.369140352285587e-05" izz="3.26650633926036e-05"/>
		</inertial>
		<collision name="4_v3:1_collision">
			<origin rpy="-0.6733194851510301 9.629649721936179e-33 1.2232983739861899e-16" xyz="-0.010000000000000009 0.045252456314776424 -0.07894610321909024"/>
			<geometry>
				<mesh filename="./meshes/4_v3.stl" scale="1.0 1.0 1.0"/>
			</geometry>
		</collision>
		<visual name="4_v3:1_visual">
			<origin rpy="-0.6733194851510301 9.629649721936179e-33 1.2232983739861899e-16" xyz="-0.010000000000000009 0.045252456314776424 -0.07894610321909024"/>
			<geometry>
				<mesh filename="./meshes/4_v3.stl" scale="1.0 1.0 1.0"/>
			</geometry>
		</visual>
	</link>
	<joint name="rev0" type="continuous">
		<parent link="base_v2:1"/>
		<child link="1_v3:1"/>
		<origin rpy="0 0 0" xyz="0.15 0.024999999999999994 -1.6840380863106523e-18"/>
		<axis xyz="-1.0 0.0 0.0"/>
	</joint>
	<joint name="rev1" type="continuous">
		<parent link="base_v2:1"/>
		<child link="2_v1:1"/>
		<origin rpy="0 0 0" xyz="0.15 -0.025 0.0"/>
		<axis xyz="-1.0 0.0 0.0"/>
	</joint>
	<joint name="rev2" type="continuous">
		<parent link="1_v3:1"/>
		<child link="3_v1:1"/>
		<origin rpy="0 0 0" xyz="0.0050000000000000044 -0.12161581418266237 -0.15877529323130896"/>
		<axis xyz="1.0 6.123233995736766e-17 0.0"/>
	</joint>
	<joint name="rev3" type="continuous">
		<parent link="4_v3:1"/>
		<child link="2_v1:1"/>
		<origin rpy="0 0 0" xyz="-0.004999999999999977 0.04525245631477645 -0.07894610321909024"/>
		<axis xyz="1.0 1.2232983739861899e-16 -9.629649721936179e-33"/>
	</joint>
	<joint name="rev4" type="continuous">
		<parent link="3_v1:1"/>
		<child link="4_v3:1"/>
		<origin rpy="0 0 0" xyz="-2.7755575615628914e-17 -0.10119553421787103 0.11072246318773662"/>
		<axis xyz="1.0 5.004030080335416e-17 0.0"/>
	</joint>
</robot>
